Workbook

Sheet Tabela
A1: Miejsce | B1: klub | C1: logo | D1: liga | E1: mecze | F1: punkty | G1: strzelone | H1: stracone | I1: wygrane | J1: remisy | K1: porażki | L1: bilans
A2: 1 | B2: Arsenal | C2: =IMAGE("https://upload.wikimedia.org/wikipedia/en/5/53/Arsenal_FC.svg") | D2: =IMAGE("https://flagcdn.com/w320/gb-eng.png") | E2: =Arsenal!H63 -> 7 | F2: =Arsenal!I63 -> 21 | G2: =Arsenal!J63 -> 20 | H2: =Arsenal!K63 -> 2 | I2: =Arsenal!L63 -> 7 | J2: =Arsenal!M63 -> 0 | K2: =Arsenal!N63 -> 0 | L2: =G2-H2 -> 18
A3: 2 | B3: Bayern Monachium | C3: =IMAGE("https://upload.wikimedia.org/wikipedia/commons/1/1b/FC_Bayern_M%C3%BCnchen_logo_%282017%29.svg") | D3: =IMAGE("https://flagcdn.com/w320/de.png") | E3: =Bayern!H36 -> 7 | F3: =Bayern!I36 -> 18 | G3: =Bayern!J36 -> 20 | H3: =Bayern!K36 -> 7 | I3: =Bayern!L36 -> 6 | J3: =Bayern!M36 -> 0 | K3: =Bayern!N36 -> 1 | L3: =G3-H3 -> 13
A4: 3 | B4: Atalanta | C4: =IMAGE("https://upload.wikimedia.org/wikipedia/commons/8/81/Logo_Atalanta_Bergamo.svg") | D4: =IMAGE("https://flagcdn.com/w320/it.png") | E4: =Atalanta!H34 -> 7 | F4: =Atalanta!I34 -> 13 | G4: =Atalanta!J34 -> 10 | H4: =Atalanta!K34 -> 9 | I4: =Atalanta!L34 -> 4 | J4: =Atalanta!M34 -> 1 | K4: =Atalanta!N34 -> 2 | L4: =G4-H4 -> 1
A5: 4 | B5: Paris Saint-Germain | C5: =IMAGE("https://upload.wikimedia.org/wikipedia/en/a/a7/Paris_Saint-Germain_F.C..svg") | D5: =IMAGE("https://flagcdn.com/w320/fr.png") | E5: =PSG!H33 -> 7 | F5: =PSG!I33 -> 13 | G5: =PSG!J33 -> 20 | H5: =PSG!K33 -> 10 | I5: =PSG!L33 -> 4 | J5: =PSG!M33 -> 1 | K5: =PSG!N33 -> 2 | L5: =G5-H5 -> 10
A6: 5 | B6: Inter Mediolan | C6: =IMAGE("https://upload.wikimedia.org/wikipedia/commons/0/05/FC_Internazionale_Milano_2021.svg") | D6: =IMAGE("https://flagcdn.com/w320/it.png") | E6: =Inter!H33 -> 7 | F6: =Inter!I33 -> 12 | G6: =Inter!J33 -> 13 | H6: =Inter!K33 -> 7 | I6: =Inter!L33 -> 4 | J6: =Inter!M33 -> 0 | K6: =Inter!N33 -> 3 | L6: =G6-H6 -> 6
A7: 6 | B7: Real Madryt | C7: =IMAGE("https://upload.wikimedia.org/wikipedia/en/5/56/Real_Madrid_CF.svg") | D7: =IMAGE("https://flagcdn.com/w320/es.png") | E7: =Real!H47 -> 7 | F7: =Real!I47 -> 15 | G7: =Real!J47 -> 19 | H7: =Real!K47 -> 8 | I7: =Real!L47 -> 5 | J7: =Real!M47 -> 0 | K7: =Real!N47 -> 2 | L7: =G7-H7 -> 11
A8: 7 | B8: Liverpool | C8: =IMAGE("https://upload.wikimedia.org/wikipedia/en/0/0c/Liverpool_FC.svg") | D8: =IMAGE("https://flagcdn.com/w320/gb-eng.png") | E8: =Liverpool!H32 -> 6 | F8: =Liverpool!I32 -> 12 | G8: =Liverpool!J32 -> 11 | H8: =Liverpool!K32 -> 8 | I8: =Liverpool!L32 -> 4 | J8: =Liverpool!M32 -> 0 | K8: =Liverpool!N32 -> 2 | L8: =G8-H8 -> 3
A9: 8 | B9: Atlético Madryt | C9: =IMAGE("https://upload.wikimedia.org/wikinews/en/c/c1/Atletico_Madrid_logo.svg") | D9: =IMAGE("https://flagcdn.com/w320/es.png") | E9: =Atletico!H44 -> 7 | F9: =Atletico!I44 -> 13 | G9: =Atletico!J44 -> 16 | H9: =Atletico!K44 -> 12 | I9: =Atletico!L44 -> 4 | J9: =Atletico!M44 -> 1 | K9: =Atletico!N44 -> 2 | L9: =G9-H9 -> 4
A10: 9 | B10: Tottenham Hotspur | C10: =IMAGE("https://upload.wikimedia.org/wikipedia/en/b/b4/Tottenham_Hotspur.svg") | D10: =IMAGE("https://flagcdn.com/w320/gb-eng.png") | E10: =Tottenham!H39 -> 7 | F10: =Tottenham!I39 -> 14 | G10: =Tottenham!J39 -> 15 | H10: =Tottenham!K39 -> 7 | I10: =Tottenham!L39 -> 4 | J10: =Tottenham!M39 -> 2 | K10: =Tottenham!N39 -> 1 | L10: =G10-H10 -> 8
A11: 10 | B11: Borussia Dortmund | C11: =IMAGE("https://upload.wikimedia.org/wikipedia/commons/6/67/Borussia_Dortmund_logo.svg") | D11: =IMAGE("https://flagcdn.com/w320/de.png") | E11: =Borussia!H32 -> 7 | F11: =Borussia!I32 -> 11 | G11: =Borussia!J32 -> 19 | H11: =Borussia!K32 -> 15 | I11: =Borussia!L32 -> 3 | J11: =Borussia!M32 -> 2 | K11: =Borussia!N32 -> 2 | L11: =G11-H11 -> 4
A12: 11 | B12: Chelsea | C12: =IMAGE("https://upload.wikimedia.org/wikipedia/en/c/cc/Chelsea_FC.svg") | D12: =IMAGE("https://flagcdn.com/w320/gb-eng.png") | E12: =Chelsea!H38 -> 7 | F12: =Chelsea!I38 -> 13 | G12: =Chelsea!J38 -> 14 | H12: =Chelsea!K38 -> 8 | I12: =Chelsea!L38 -> 4 | J12: =Chelsea!M38 -> 1 | K12: =Chelsea!N38 -> 2 | L12: =G12-H12 -> 6
A13: 12 | B13: Manchester City | C13: =IMAGE("https://upload.wikimedia.org/wikipedia/en/e/eb/Manchester_City_FC_badge.svg") | D13: =IMAGE("https://flagcdn.com/w320/gb-eng.png") | E13: =City!H36 -> 7 | F13: =City!I36 -> 13 | G13: =City!J36 -> 13 | H13: =City!K36 -> 9 | I13: =City!L36 -> 4 | J13: =City!M36 -> 1 | K13: =City!N36 -> 2 | L13: =G13-H13 -> 4
A14: 13 | B14: Sporting CP | C14: =IMAGE("https://upload.wikimedia.org/wikipedia/sco/3/3e/Sporting_Clube_de_Portugal.png") | D14: =IMAGE("https://flagcdn.com/w320/pt.png") | E14: =Sporting!H41 -> 7 | F14: =Sporting!I41 -> 13 | G14: =Sporting!J41 -> 14 | H14: =Sporting!K41 -> 9 | I14: =Sporting!L41 -> 4 | J14: =Sporting!M41 -> 1 | K14: =Sporting!N41 -> 2 | L14: =G14-H14 -> 5
A15: 14 | B15: Barcelona | C15: =IMAGE("https://upload.wikimedia.org/wikipedia/en/4/47/FC_Barcelona_%28crest%29.svg") | D15: =IMAGE("https://flagcdn.com/w320/es.png") | E15: =Barcelona!H37 -> 7 | F15: =Barcelona!I37 -> 13 | G15: =Barcelona!J37 -> 18 | H15: =Barcelona!K37 -> 13 | I15: =Barcelona!L37 -> 4 | J15: =Barcelona!M37 -> 1 | K15: =Barcelona!N37 -> 2 | L15: =G15-H15 -> 5
A16: 15 | B16: Newcastle United | C16: =IMAGE("https://upload.wikimedia.org/wikipedia/en/5/56/Newcastle_United_Logo.svg") | D16: =IMAGE("https://flagcdn.com/w320/gb-eng.png") | E16: =Newcastle!H34 -> 7 | F16: =Newcastle!I34 -> 13 | G16: =Newcastle!J34 -> 16 | H16: =Newcastle!K34 -> 6 | I16: =Newcastle!L34 -> 4 | J16: =Newcastle!M34 -> 1 | K16: =Newcastle!N34 -> 2 | L16: =G16-H16 -> 10
A17: 16 | B17: Galatasaray | C17: =IMAGE("https://upload.wikimedia.org/wikipedia/commons/2/20/Galatasaray_Sports_Club_Logo.svg") | D17: =IMAGE("https://flagcdn.com/w320/tr.png") | E17: =Galatasaray!H34 -> 7 | F17: =Galatasaray!I34 -> 10 | G17: =Galatasaray!J34 -> 9 | H17: =Galatasaray!K34 -> 9 | I17: =Galatasaray!L34 -> 3 | J17: =Galatasaray!M34 -> 1 | K17: =Galatasaray!N34 -> 3 | L17: =G17-H17 -> 0
A18: 17 | B18: Marsylia | C18: =IMAGE("https://upload.wikimedia.org/wikipedia/commons/d/d8/Olympique_Marseille_logo.svg") | D18: =IMAGE("https://flagcdn.com/w320/fr.png") | E18: =Marsylia!H47 -> 7 | F18: =Marsylia!I47 -> 9 | G18: =Marsylia!J47 -> 11 | H18: =Marsylia!K47 -> 11 | I18: =Marsylia!L47 -> 3 | J18: =Marsylia!M47 -> 0 | K18: =Marsylia!N47 -> 4 | L18: =G18-H18 -> 0
A19: 18 | B19: Monaco | C19: =IMAGE("https://upload.wikimedia.org/wikipedia/fr/5/58/Logo_AS_Monaco_FC_-_2021.svg") | D19: =IMAGE("https://flagcdn.com/w320/fr.png") | E19: =Monaco!H40 -> 7 | F19: =Monaco!I40 -> 9 | G19: =Monaco!J40 -> 8 | H19: =Monaco!K40 -> 14 | I19: =Monaco!L40 -> 2 | J19: =Monaco!M40 -> 3 | K19: =Monaco!N40 -> 2 | L19: =G19-H19 -> -6
A20: 19 | B20: PSV Eindhoven | C20: =IMAGE("https://upload.wikimedia.org/wikipedia/en/0/05/PSV_Eindhoven.svg") | D20: =IMAGE("https://flagcdn.com/w320/nl.png") | E20: =PSV!H60 -> 7 | F20: =PSV!I60 -> 8 | G20: =PSV!J60 -> 15 | H20: =PSV!K60 -> 14 | I20: =PSV!L60 -> 2 | J20: =PSV!M60 -> 2 | K20: =PSV!N60 -> 3 | L20: =G20-H20 -> 1
A21: 20 | B21: Bayer Leverkusen | C21: =IMAGE("https://upload.wikimedia.org/wikipedia/en/5/59/Bayer_04_Leverkusen_logo.svg") | D21: =IMAGE("https://flagcdn.com/w320/de.png") | E21: =Leverkusen!H37 -> 7 | F21: =Leverkusen!I37 -> 9 | G21: =Leverkusen!J37 -> 10 | H21: =Leverkusen!K37 -> 14 | I21: =Leverkusen!L37 -> 2 | J21: =Leverkusen!M37 -> 3 | K21: =Leverkusen!N37 -> 2 | L21: =G21-H21 -> -4
A22: 21 | B22: Karabach | C22: =IMAGE("https://upload.wikimedia.org/wikipedia/az/1/13/Qaraba%C4%9F_FK_loqo.png") | D22: =IMAGE("https://flagcdn.com/w320/az.png") | E22: =Karabach!H31 -> 7 | F22: =Karabach!I31 -> 10 | G22: =Karabach!J31 -> 13 | H22: =Karabach!K31 -> 15 | I22: =Karabach!L31 -> 3 | J22: =Karabach!M31 -> 1 | K22: =Karabach!N31 -> 3 | L22: =G22-H22 -> -2
A23: 22 | B23: Napoli | C23: =IMAGE("https://upload.wikimedia.org/wikipedia/commons/4/4d/SSC_Napoli_2025_%28white_and_azure%29.svg") | D23: =IMAGE("https://flagcdn.com/w320/it.png") | E23: =Napoli!H33 -> 7 | F23: =Napoli!I33 -> 8 | G23: =Napoli!J33 -> 7 | H23: =Napoli!K33 -> 12 | I23: =Napoli!L33 -> 2 | J23: =Napoli!M33 -> 2 | K23: =Napoli!N33 -> 3 | L23: =G23-H23 -> -5
A24: 23 | B24: Kopenhaga | C24: =IMAGE("https://upload.wikimedia.org/wikipedia/en/2/26/FC_Copenhagen_logo.svg") | D24: =IMAGE("https://flagcdn.com/w320/dk.png") | E24: =Kopenhaga!H34 -> 7 | F24: =Kopenhaga!I34 -> 8 | G24: =Kopenhaga!J34 -> 11 | H24: =Kopenhaga!K34 -> 17 | I24: =Kopenhaga!L34 -> 2 | J24: =Kopenhaga!M34 -> 2 | K24: =Kopenhaga!N34 -> 3 | L24: =G24-H24 -> -6
A25: 24 | B25: Juventus | C25: =IMAGE("https://upload.wikimedia.org/wikipedia/commons/e/ed/Juventus_FC_-_logo_black_%28Italy%2C_2020%29.svg") | D25: =IMAGE("https://flagcdn.com/w320/it.png") | E25: =Juventus!H35 -> 7 | F25: =Juventus!I35 -> 12 | G25: =Juventus!J35 -> 14 | H25: =Juventus!K35 -> 10 | I25: =Juventus!L35 -> 3 | J25: =Juventus!M35 -> 3 | K25: =Juventus!N35 -> 1 | L25: =G25-H25 -> 4
A26: 25 | B26: Pafos | C26: =IMAGE("https://upload.wikimedia.org/wikipedia/en/9/9b/Pafos_FC_crest.svg") | D26: =IMAGE("https://flagcdn.com/w320/cy.png") | E26: =Pafos!H29 -> 7 | F26: =Pafos!I29 -> 6 | G26: =Pafos!J29 -> 4 | H26: =Pafos!K29 -> 10 | I26: =Pafos!L29 -> 1 | J26: =Pafos!M29 -> 3 | K26: =Pafos!N29 -> 3 | L26: =G26-H26 -> -6
A27: 26 | B27: Union Saint-Gilloise | C27: =IMAGE("https://upload.wikimedia.org/wikipedia/en/0/02/Royale_Union_Saint-Gilloise_logo.png") | D27: =IMAGE("https://flagcdn.com/w320/be.png") | E27: =USG!H38 -> 7 | F27: =USG!I38 -> 6 | G27: =USG!J38 -> 7 | H27: =USG!K38 -> 17 | I27: =USG!L38 -> 2 | J27: =USG!M38 -> 0 | K27: =USG!N38 -> 5 | L27: =G27-H27 -> -10
A28: 27 | B28: Olympiacos | C28: =IMAGE("https://upload.wikimedia.org/wikipedia/en/a/a2/Olympiacos_FC_crest.svg") | D28: =IMAGE("https://flagcdn.com/w320/gr.png") | E28: =Olympiacos!H32 -> 7 | F28: =Olympiacos!I32 -> 8 | G28: =Olympiacos!J32 -> 8 | H28: =Olympiacos!K32 -> 13 | I28: =Olympiacos!L32 -> 2 | J28: =Olympiacos!M32 -> 2 | K28: =Olympiacos!N32 -> 3 | L28: =G28-H28 -> -5
A29: 28 | B29: Club Brugge | C29: =IMAGE("https://upload.wikimedia.org/wikipedia/en/d/d0/Club_Brugge_KV_logo.svg") | D29: =IMAGE("https://flagcdn.com/w320/be.png") | E29: =Brugge!H41 -> 7 | F29: =Brugge!I41 -> 7 | G29: =Brugge!J41 -> 12 | H29: =Brugge!K41 -> 17 | I29: =Brugge!L41 -> 2 | J29: =Brugge!M41 -> 1 | K29: =Brugge!N41 -> 4 | L29: =G29-H29 -> -5
A30: 29 | B30: Athletic Bilbao | C30: =IMAGE("https://upload.wikimedia.org/wikipedia/en/9/98/Club_Athletic_Bilbao_logo.svg") | D30: =IMAGE("https://flagcdn.com/w320/es.png") | E30: =Athletic!H38 -> 7 | F30: =Athletic!I38 -> 8 | G30: =Athletic!J38 -> 7 | H30: =Athletic!K38 -> 11 | I30: =Athletic!L38 -> 2 | J30: =Athletic!M38 -> 2 | K30: =Athletic!N38 -> 3 | L30: =G30-H30 -> -4
A31: 30 | B31: Eintracht Frankfurt | C31: =IMAGE("https://upload.wikimedia.org/wikipedia/en/7/7e/Eintracht_Frankfurt_crest.svg") | D31: =IMAGE("https://flagcdn.com/w320/de.png") | E31: =Frankfurt!H39 -> 7 | F31: =Frankfurt!I39 -> 4 | G31: =Frankfurt!J39 -> 10 | H31: =Frankfurt!K39 -> 19 | I31: =Frankfurt!L39 -> 1 | J31: =Frankfurt!M39 -> 1 | K31: =Frankfurt!N39 -> 5 | L31: =G31-H31 -> -9
A32: 31 | B32: Benfica | C32: =IMAGE("https://upload.wikimedia.org/wikipedia/en/a/a2/SL_Benfica_logo.svg") | D32: =IMAGE("https://flagcdn.com/w320/pt.png") | E32: =Benfica!H41 -> 7 | F32: =Benfica!I41 -> 6 | G32: =Benfica!J41 -> 6 | H32: =Benfica!K41 -> 10 | I32: =Benfica!L41 -> 2 | J32: =Benfica!M41 -> 0 | K32: =Benfica!N41 -> 5 | L32: =G32-H32 -> -4
A33: 32 | B33: Ajax | C33: =IMAGE("https://upload.wikimedia.org/wikipedia/en/7/79/Ajax_Amsterdam.svg") | D33: =IMAGE("https://flagcdn.com/w320/nl.png") | E33: =Ajax!H53 -> 7 | F33: =Ajax!I53 -> 6 | G33: =Ajax!J53 -> 7 | H33: =Ajax!K53 -> 19 | I33: =Ajax!L53 -> 2 | J33: =Ajax!M53 -> 0 | K33: =Ajax!N53 -> 5 | L33: =G33-H33 -> -12
A34: 33 | B34: Bodø/Glimt | C34: =IMAGE("https://upload.wikimedia.org/wikipedia/en/8/8d/FK_Bodo_Glimt_logo.svg") | D34: =IMAGE("https://flagcdn.com/w320/no.png") | E34: =Bodo!H37 -> 7 | F34: =Bodo!I37 -> 6 | G34: =Bodo!J37 -> 12 | H34: =Bodo!K37 -> 14 | I34: =Bodo!L37 -> 1 | J34: =Bodo!M37 -> 3 | K34: =Bodo!N37 -> 3 | L34: =G34-H34 -> -2
A35: 34 | B35: Slavia Praga | C35: =IMAGE("https://upload.wikimedia.org/wikipedia/commons/2/2b/SK_Slavia_Praha_full_logo.svg") | D35: =IMAGE("https://flagcdn.com/w320/cz.png") | E35: =Slavia!H44 -> 7 | F35: =Slavia!I44 -> 3 | G35: =Slavia!J44 -> 4 | H35: =Slavia!K44 -> 15 | I35: =Slavia!L44 -> 0 | J35: =Slavia!M44 -> 3 | K35: =Slavia!N44 -> 4 | L35: =G35-H35 -> -11
A36: 35 | B36: Villarreal | C36: =IMAGE("https://upload.wikimedia.org/wikipedia/en/b/b9/Villarreal_CF_logo-en.svg") | D36: =IMAGE("https://flagcdn.com/w320/es.png") | E36: =Villarreal!H34 -> 7 | F36: =Villarreal!I34 -> 1 | G36: =Villarreal!J34 -> 5 | H36: =Villarreal!K34 -> 15 | I36: =Villarreal!L34 -> 0 | J36: =Villarreal!M34 -> 1 | K36: =Villarreal!N34 -> 6 | L36: =G36-H36 -> -10
A37: 36 | B37: Kairat | C37: =IMAGE("https://upload.wikimedia.org/wikipedia/commons/1/1b/FCKairat_logo.png") | D37: =IMAGE("https://flagcdn.com/w320/kz.png") | E37: =Kairat!H42 -> 7 | F37: =Kairat!I42 -> 1 | G37: =Kairat!J42 -> 5 | H37: =Kairat!K42 -> 19 | I37: =Kairat!L42 -> 0 | J37: =Kairat!M42 -> 1 | K37: =Kairat!N42 -> 6 | L37: =G37-H37 -> -14

Sheet Strzelcy
A1: Miejsce | B1: numer | C1: imię i nazwisko | D1: pozycja | E1: kraj | F1: data urodzenia | G1: wiek | H1: liczba goli
A2: 1 | B2: =IFERROR(__xludf.DUMMYFUNCTION("QUERY({Ajax!A2:G1001,Ajax!J2:J1001; Arsenal!A2:G1001,Arsenal!J2:J1001; Atalanta!A2:G1001,Atalanta!J2:J1001; Athletic!A2:G1001,Athletic!J2:J1001; Atletico!A2:G1001,Atletico!J2:J1001; Borussia!A2:G1001,Borussia!J2:J1001; Barcelona!A2:G1001,Barcelona!J2:J100"&"1; Bayern!A2:G1001,Bayern!J2:J1001; Benfica!A2:G1001,Benfica!J2:J1001; Bodo!A2:G1001,Bodo!J2:J1001; Chelsea!A2:G1001,Chelsea!J2:J1001; Brugge!A2:G1001,Brugge!J2:J1001; Kopenhaga!A2:G1001,Kopenhaga!J2:J1001; Frankfurt!A2:G1001,Frankfurt!J2:J1001; Galatasar"&"ay!A2:G1001,Galatasaray!J2:J1001; Inter!A2:G1001,Inter!J2:J1001; Kairat!A2:G1001,Kairat!J2:J1001; Juventus!A2:G1001,Juventus!J2:J1001; Leverkusen!A2:G1001,Leverkusen!J2:J1001; Liverpool!A2:G1001,Liverpool!J2:J1001; City!A2:G1001,City!J2:J1001; Marsylia!A2"&":G1001,Marsylia!J2:J1001; Monaco!A2:G1001,Monaco!J2:J1001; Napoli!A2:G1001,Napoli!J2:J1001; Newcastle!A2:G1001,Newcastle!J2:J1001; Olympiacos!A2:G1001,Olympiacos!J2:J1001; Pafos!A2:G1001,Pafos!J2:J1001; PSG!A2:G1001,PSG!J2:J1001; PSV!A2:G1001,PSV!J2:J1001"&"; Real!A2:G1001,Real!J2:J1001; Slavia!A2:G1001,Slavia!J2:J1001; Sporting!A2:G1001,Sporting!J2:J1001; Karabach!A2:G1001,Karabach!J2:J1001; Tottenham!A2:G1001,Tottenham!J2:J1001; USG!A2:G1001,USG!J2:J1001; Villarreal!A2:G1001,Villarreal!J2:J1001},""SELECT C"&"ol1, Col2, Col3, Col4, Col6, Col7, Col8 WHERE Col8 IS NOT NULL AND NOT Col3 CONTAINS 'trener' AND NOT Col3 CONTAINS 'trenera' AND Col1 IS NOT NULL ORDER BY Col8 DESC"")"),10.0) -> 10 | C2: =IFERROR(__xludf.DUMMYFUNCTION("""COMPUTED_VALUE"""),"Kylian Mbappé") -> Kylian Mbappé | D2: =IFERROR(__xludf.DUMMYFUNCTION("""COMPUTED_VALUE"""),"napastnik") -> napastnik | E2: =IFERROR(__xludf.DUMMYFUNCTION("""COMPUTED_VALUE"""),"Francja /Kamerun") -> Francja /Kamerun | F2: =IFERROR(__xludf.DUMMYFUNCTION("""COMPUTED_VALUE"""),36149.0) -> 36149 | G2: =IFERROR(__xludf.DUMMYFUNCTION("""COMPUTED_VALUE"""),27.0) -> 27 | H2: =IFERROR(__xludf.DUMMYFUNCTION("""COMPUTED_VALUE"""),11.0) -> 11
A3: 2 | B3: =IFERROR(__xludf.DUMMYFUNCTION("""COMPUTED_VALUE"""),9.0) -> 9 | C3: =IFERROR(__xludf.DUMMYFUNCTION("""COMPUTED_VALUE"""),"Harry Kane") -> Harry Kane | D3: =IFERROR(__xludf.DUMMYFUNCTION("""COMPUTED_VALUE"""),"napastnik") -> napastnik | E3: =IFERROR(__xludf.DUMMYFUNCTION("""COMPUTED_VALUE"""),"Anglia") -> Anglia | F3: =IFERROR(__xludf.DUMMYFUNCTION("""COMPUTED_VALUE"""),34178.0) -> 34178 | G3: =IFERROR(__xludf.DUMMYFUNCTION("""COMPUTED_VALUE"""),32.0) -> 32 | H3: =IFERROR(__xludf.DUMMYFUNCTION("""COMPUTED_VALUE"""),7.0) -> 7
A4: 3 | B4: =IFERROR(__xludf.DUMMYFUNCTION("""COMPUTED_VALUE"""),45.0) -> 45 | C4: =IFERROR(__xludf.DUMMYFUNCTION("""COMPUTED_VALUE"""),"Victor Osimhen") -> Victor Osimhen | D4: =IFERROR(__xludf.DUMMYFUNCTION("""COMPUTED_VALUE"""),"napastnik") -> napastnik | E4: =IFERROR(__xludf.DUMMYFUNCTION("""COMPUTED_VALUE"""),"Nigeria") -> Nigeria | F4: =IFERROR(__xludf.DUMMYFUNCTION("""COMPUTED_VALUE"""),36158.0) -> 36158 | G4: =IFERROR(__xludf.DUMMYFUNCTION("""COMPUTED_VALUE"""),27.0) -> 27 | H4: =IFERROR(__xludf.DUMMYFUNCTION("""COMPUTED_VALUE"""),6.0) -> 6
A5: 4 | B5: =IFERROR(__xludf.DUMMYFUNCTION("""COMPUTED_VALUE"""),9.0) -> 9 | C5: =IFERROR(__xludf.DUMMYFUNCTION("""COMPUTED_VALUE"""),"Erling Haaland") -> Erling Haaland | D5: =IFERROR(__xludf.DUMMYFUNCTION("""COMPUTED_VALUE"""),"napastnik") -> napastnik | E5: =IFERROR(__xludf.DUMMYFUNCTION("""COMPUTED_VALUE"""),"Norwegia") -> Norwegia | F5: =IFERROR(__xludf.DUMMYFUNCTION("""COMPUTED_VALUE"""),36728.0) -> 36728 | G5: =IFERROR(__xludf.DUMMYFUNCTION("""COMPUTED_VALUE"""),25.0) -> 25 | H5: =IFERROR(__xludf.DUMMYFUNCTION("""COMPUTED_VALUE"""),6.0) -> 6
A6: 5 | B6: =IFERROR(__xludf.DUMMYFUNCTION("""COMPUTED_VALUE"""),10.0) -> 10 | C6: =IFERROR(__xludf.DUMMYFUNCTION("""COMPUTED_VALUE"""),"Anthony Gordon") -> Anthony Gordon | D6: =IFERROR(__xludf.DUMMYFUNCTION("""COMPUTED_VALUE"""),"napastnik") -> napastnik | E6: =IFERROR(__xludf.DUMMYFUNCTION("""COMPUTED_VALUE"""),"Anglia") -> Anglia | F6: =IFERROR(__xludf.DUMMYFUNCTION("""COMPUTED_VALUE"""),36946.0) -> 36946 | G6: =IFERROR(__xludf.DUMMYFUNCTION("""COMPUTED_VALUE"""),24.0) -> 24 | H6: =IFERROR(__xludf.DUMMYFUNCTION("""COMPUTED_VALUE"""),6.0) -> 6
A7: 6 | B7: =IFERROR(__xludf.DUMMYFUNCTION("""COMPUTED_VALUE"""),11.0) -> 11 | C7: =IFERROR(__xludf.DUMMYFUNCTION("""COMPUTED_VALUE"""),"Gabriel Martinelli") -> Gabriel Martinelli | D7: =IFERROR(__xludf.DUMMYFUNCTION("""COMPUTED_VALUE"""),"napastnik") -> napastnik | E7: =IFERROR(__xludf.DUMMYFUNCTION("""COMPUTED_VALUE"""),"Brazylia /Włochy") -> Brazylia /Włochy | F7: =IFERROR(__xludf.DUMMYFUNCTION("""COMPUTED_VALUE"""),37060.0) -> 37060 | G7: =IFERROR(__xludf.DUMMYFUNCTION("""COMPUTED_VALUE"""),24.0) -> 24 | H7: =IFERROR(__xludf.DUMMYFUNCTION("""COMPUTED_VALUE"""),5.0) -> 5
A8: 7 | B8: =IFERROR(__xludf.DUMMYFUNCTION("""COMPUTED_VALUE"""),16.0) -> 16 | C8: =IFERROR(__xludf.DUMMYFUNCTION("""COMPUTED_VALUE"""),"Fermín López") -> Fermín López | D8: =IFERROR(__xludf.DUMMYFUNCTION("""COMPUTED_VALUE"""),"pomocnik") -> pomocnik | E8: =IFERROR(__xludf.DUMMYFUNCTION("""COMPUTED_VALUE"""),"Hiszpania") -> Hiszpania | F8: =IFERROR(__xludf.DUMMYFUNCTION("""COMPUTED_VALUE"""),37752.0) -> 37752 | G8: =IFERROR(__xludf.DUMMYFUNCTION("""COMPUTED_VALUE"""),22.0) -> 22 | H8: =IFERROR(__xludf.DUMMYFUNCTION("""COMPUTED_VALUE"""),5.0) -> 5
A9: 8 | B9: =IFERROR(__xludf.DUMMYFUNCTION("""COMPUTED_VALUE"""),11.0) -> 11 | C9: =IFERROR(__xludf.DUMMYFUNCTION("""COMPUTED_VALUE"""),"Harvey Barnes") -> Harvey Barnes | D9: =IFERROR(__xludf.DUMMYFUNCTION("""COMPUTED_VALUE"""),"pomocnik") -> pomocnik | E9: =IFERROR(__xludf.DUMMYFUNCTION("""COMPUTED_VALUE"""),"Anglia") -> Anglia | F9: =IFERROR(__xludf.DUMMYFUNCTION("""COMPUTED_VALUE"""),35773.0) -> 35773 | G9: =IFERROR(__xludf.DUMMYFUNCTION("""COMPUTED_VALUE"""),28.0) -> 28 | H9: =IFERROR(__xludf.DUMMYFUNCTION("""COMPUTED_VALUE"""),5.0) -> 5
A10: 9 | B10: =IFERROR(__xludf.DUMMYFUNCTION("""COMPUTED_VALUE"""),11.0) -> 11 | C10: =IFERROR(__xludf.DUMMYFUNCTION("""COMPUTED_VALUE"""),"Gorka Guruzeta") -> Gorka Guruzeta | D10: =IFERROR(__xludf.DUMMYFUNCTION("""COMPUTED_VALUE"""),"napastnik") -> napastnik | E10: =IFERROR(__xludf.DUMMYFUNCTION("""COMPUTED_VALUE"""),"Hiszpania") -> Hiszpania | F10: =IFERROR(__xludf.DUMMYFUNCTION("""COMPUTED_VALUE"""),35320.0) -> 35320 | G10: =IFERROR(__xludf.DUMMYFUNCTION("""COMPUTED_VALUE"""),29.0) -> 29 | H10: =IFERROR(__xludf.DUMMYFUNCTION("""COMPUTED_VALUE"""),4.0) -> 4
A11: 10 | B11: =IFERROR(__xludf.DUMMYFUNCTION("""COMPUTED_VALUE"""),19.0) -> 19 | C11: =IFERROR(__xludf.DUMMYFUNCTION("""COMPUTED_VALUE"""),"Julián Alvarez") -> Julián Alvarez | D11: =IFERROR(__xludf.DUMMYFUNCTION("""COMPUTED_VALUE"""),"napastnik") -> napastnik | E11: =IFERROR(__xludf.DUMMYFUNCTION("""COMPUTED_VALUE"""),"Argentyna /Włochy") -> Argentyna /Włochy | F11: =IFERROR(__xludf.DUMMYFUNCTION("""COMPUTED_VALUE"""),36556.0) -> 36556 | G11: =IFERROR(__xludf.DUMMYFUNCTION("""COMPUTED_VALUE"""),25.0) -> 25 | H11: =IFERROR(__xludf.DUMMYFUNCTION("""COMPUTED_VALUE"""),4.0) -> 4
A12: 11 | B12: =IFERROR(__xludf.DUMMYFUNCTION("""COMPUTED_VALUE"""),14.0) -> 14 | C12: =IFERROR(__xludf.DUMMYFUNCTION("""COMPUTED_VALUE"""),"Marcus Rashford") -> Marcus Rashford | D12: =IFERROR(__xludf.DUMMYFUNCTION("""COMPUTED_VALUE"""),"napastnik") -> napastnik | E12: =IFERROR(__xludf.DUMMYFUNCTION("""COMPUTED_VALUE"""),"Anglia /St. Kitts i Nevis") -> Anglia /St. Kitts i Nevis | F12: =IFERROR(__xludf.DUMMYFUNCTION("""COMPUTED_VALUE"""),35734.0) -> 35734 | G12: =IFERROR(__xludf.DUMMYFUNCTION("""COMPUTED_VALUE"""),28.0) -> 28 | H12: =IFERROR(__xludf.DUMMYFUNCTION("""COMPUTED_VALUE"""),4.0) -> 4
A13: 12 | B13: =IFERROR(__xludf.DUMMYFUNCTION("""COMPUTED_VALUE"""),10.0) -> 10 | C13: =IFERROR(__xludf.DUMMYFUNCTION("""COMPUTED_VALUE"""),"Jens Petter Hauge") -> Jens Petter Hauge | D13: =IFERROR(__xludf.DUMMYFUNCTION("""COMPUTED_VALUE"""),"napastnik") -> napastnik | E13: =IFERROR(__xludf.DUMMYFUNCTION("""COMPUTED_VALUE"""),"Norwegia") -> Norwegia | F13: =IFERROR(__xludf.DUMMYFUNCTION("""COMPUTED_VALUE"""),36445.0) -> 36445 | G13: =IFERROR(__xludf.DUMMYFUNCTION("""COMPUTED_VALUE"""),26.0) -> 26 | H13: =IFERROR(__xludf.DUMMYFUNCTION("""COMPUTED_VALUE"""),4.0) -> 4
A14: 13 | B14: =IFERROR(__xludf.DUMMYFUNCTION("""COMPUTED_VALUE"""),10.0) -> 10 | C14: =IFERROR(__xludf.DUMMYFUNCTION("""COMPUTED_VALUE"""),"Lautaro Martínez") -> Lautaro Martínez | D14: =IFERROR(__xludf.DUMMYFUNCTION("""COMPUTED_VALUE"""),"napastnik") -> napastnik | E14: =IFERROR(__xludf.DUMMYFUNCTION("""COMPUTED_VALUE"""),"Argentyna") -> Argentyna | F14: =IFERROR(__xludf.DUMMYFUNCTION("""COMPUTED_VALUE"""),35664.0) -> 35664 | G14: =IFERROR(__xludf.DUMMYFUNCTION("""COMPUTED_VALUE"""),28.0) -> 28 | H14: =IFERROR(__xludf.DUMMYFUNCTION("""COMPUTED_VALUE"""),4.0) -> 4
A15: 14 | B15: =IFERROR(__xludf.DUMMYFUNCTION("""COMPUTED_VALUE"""),8.0) -> 8 | C15: =IFERROR(__xludf.DUMMYFUNCTION("""COMPUTED_VALUE"""),"Dominik Szoboszlai") -> Dominik Szoboszlai | D15: =IFERROR(__xludf.DUMMYFUNCTION("""COMPUTED_VALUE"""),"pomocnik") -> pomocnik | E15: =IFERROR(__xludf.DUMMYFUNCTION("""COMPUTED_VALUE"""),"Węgry") -> Węgry | F15: =IFERROR(__xludf.DUMMYFUNCTION("""COMPUTED_VALUE"""),36824.0) -> 36824 | G15: =IFERROR(__xludf.DUMMYFUNCTION("""COMPUTED_VALUE"""),25.0) -> 25 | H15: =IFERROR(__xludf.DUMMYFUNCTION("""COMPUTED_VALUE"""),4.0) -> 4
A16: 15 | B16: =IFERROR(__xludf.DUMMYFUNCTION("""COMPUTED_VALUE"""),14.0) -> 14 | C16: =IFERROR(__xludf.DUMMYFUNCTION("""COMPUTED_VALUE"""),"Igor Paixão") -> Igor Paixão | D16: =IFERROR(__xludf.DUMMYFUNCTION("""COMPUTED_VALUE"""),"napastnik") -> napastnik | E16: =IFERROR(__xludf.DUMMYFUNCTION("""COMPUTED_VALUE"""),"Brazylia") -> Brazylia | F16: =IFERROR(__xludf.DUMMYFUNCTION("""COMPUTED_VALUE"""),36705.0) -> 36705 | G16: =IFERROR(__xludf.DUMMYFUNCTION("""COMPUTED_VALUE"""),25.0) -> 25 | H16: =IFERROR(__xludf.DUMMYFUNCTION("""COMPUTED_VALUE"""),4.0) -> 4
A17: 16 | B17: =IFERROR(__xludf.DUMMYFUNCTION("""COMPUTED_VALUE"""),8.0) -> 8 | C17: =IFERROR(__xludf.DUMMYFUNCTION("""COMPUTED_VALUE"""),"Scott McTominay") -> Scott McTominay | D17: =IFERROR(__xludf.DUMMYFUNCTION("""COMPUTED_VALUE"""),"pomocnik") -> pomocnik | E17: =IFERROR(__xludf.DUMMYFUNCTION("""COMPUTED_VALUE"""),"Szkocja /Anglia") -> Szkocja /Anglia | F17: =IFERROR(__xludf.DUMMYFUNCTION("""COMPUTED_VALUE"""),35407.0) -> 35407 | G17: =IFERROR(__xludf.DUMMYFUNCTION("""COMPUTED_VALUE"""),29.0) -> 29 | H17: =IFERROR(__xludf.DUMMYFUNCTION("""COMPUTED_VALUE"""),4.0) -> 4
A18: 17 | B18: =IFERROR(__xludf.DUMMYFUNCTION("""COMPUTED_VALUE"""),17.0) -> 17 | C18: =IFERROR(__xludf.DUMMYFUNCTION("""COMPUTED_VALUE"""),"Vitinha") -> Vitinha | D18: =IFERROR(__xludf.DUMMYFUNCTION("""COMPUTED_VALUE"""),"pomocnik") -> pomocnik | E18: =IFERROR(__xludf.DUMMYFUNCTION("""COMPUTED_VALUE"""),"Portugalia") -> Portugalia | F18: =IFERROR(__xludf.DUMMYFUNCTION("""COMPUTED_VALUE"""),36569.0) -> 36569 | G18: =IFERROR(__xludf.DUMMYFUNCTION("""COMPUTED_VALUE"""),25.0) -> 25 | H18: =IFERROR(__xludf.DUMMYFUNCTION("""COMPUTED_VALUE"""),4.0) -> 4
A19: 18 | B19: =IFERROR(__xludf.DUMMYFUNCTION("""COMPUTED_VALUE"""),97.0) -> 97 | C19: =IFERROR(__xludf.DUMMYFUNCTION("""COMPUTED_VALUE"""),"Luis Suárez") -> Luis Suárez | D19: =IFERROR(__xludf.DUMMYFUNCTION("""COMPUTED_VALUE"""),"napastnik") -> napastnik | E19: =IFERROR(__xludf.DUMMYFUNCTION("""COMPUTED_VALUE"""),"Kolumbia /Hiszpania") -> Kolumbia /Hiszpania | F19: =IFERROR(__xludf.DUMMYFUNCTION("""COMPUTED_VALUE"""),35766.0) -> 35766 | G19: =IFERROR(__xludf.DUMMYFUNCTION("""COMPUTED_VALUE"""),28.0) -> 28 | H19: =IFERROR(__xludf.DUMMYFUNCTION("""COMPUTED_VALUE"""),4.0) -> 4
A20: 19 | B20: =IFERROR(__xludf.DUMMYFUNCTION("""COMPUTED_VALUE"""),17.0) -> 17 | C20: =IFERROR(__xludf.DUMMYFUNCTION("""COMPUTED_VALUE"""),"Camilo Durán") -> Camilo Durán | D20: =IFERROR(__xludf.DUMMYFUNCTION("""COMPUTED_VALUE"""),"napastnik") -> napastnik | E20: =IFERROR(__xludf.DUMMYFUNCTION("""COMPUTED_VALUE"""),"Kolumbia") -> Kolumbia | F20: =IFERROR(__xludf.DUMMYFUNCTION("""COMPUTED_VALUE"""),37297.0) -> 37297 | G20: =IFERROR(__xludf.DUMMYFUNCTION("""COMPUTED_VALUE"""),23.0) -> 23 | H20: =IFERROR(__xludf.DUMMYFUNCTION("""COMPUTED_VALUE"""),4.0) -> 4
A21: 20 | B21: =IFERROR(__xludf.DUMMYFUNCTION("""COMPUTED_VALUE"""),10.0) -> 10 | C21: =IFERROR(__xludf.DUMMYFUNCTION("""COMPUTED_VALUE"""),"Oscar Gloukh") -> Oscar Gloukh | D21: =IFERROR(__xludf.DUMMYFUNCTION("""COMPUTED_VALUE"""),"pomocnik") -> pomocnik | E21: =IFERROR(__xludf.DUMMYFUNCTION("""COMPUTED_VALUE"""),"Izrael") -> Izrael | F21: =IFERROR(__xludf.DUMMYFUNCTION("""COMPUTED_VALUE"""),38078.0) -> 38078 | G21: =IFERROR(__xludf.DUMMYFUNCTION("""COMPUTED_VALUE"""),21.0) -> 21 | H21: =IFERROR(__xludf.DUMMYFUNCTION("""COMPUTED_VALUE"""),3.0) -> 3
A22: 21 | B22: =IFERROR(__xludf.DUMMYFUNCTION("""COMPUTED_VALUE"""),14.0) -> 14 | C22: =IFERROR(__xludf.DUMMYFUNCTION("""COMPUTED_VALUE"""),"Viktor Gyökeres") -> Viktor Gyökeres | D22: =IFERROR(__xludf.DUMMYFUNCTION("""COMPUTED_VALUE"""),"napastnik") -> napastnik | E22: =IFERROR(__xludf.DUMMYFUNCTION("""COMPUTED_VALUE"""),"Szwecja /Węgry") -> Szwecja /Węgry | F22: =IFERROR(__xludf.DUMMYFUNCTION("""COMPUTED_VALUE"""),35950.0) -> 35950 | G22: =IFERROR(__xludf.DUMMYFUNCTION("""COMPUTED_VALUE"""),27.0) -> 27 | H22: =IFERROR(__xludf.DUMMYFUNCTION("""COMPUTED_VALUE"""),3.0) -> 3
A23: 22 | B23: =IFERROR(__xludf.DUMMYFUNCTION("""COMPUTED_VALUE"""),20.0) -> 20 | C23: =IFERROR(__xludf.DUMMYFUNCTION("""COMPUTED_VALUE"""),"Noni Madueke") -> Noni Madueke | D23: =IFERROR(__xludf.DUMMYFUNCTION("""COMPUTED_VALUE"""),"napastnik") -> napastnik | E23: =IFERROR(__xludf.DUMMYFUNCTION("""COMPUTED_VALUE"""),"Anglia /Nigeria") -> Anglia /Nigeria | F23: =IFERROR(__xludf.DUMMYFUNCTION("""COMPUTED_VALUE"""),37325.0) -> 37325 | G23: =IFERROR(__xludf.DUMMYFUNCTION("""COMPUTED_VALUE"""),23.0) -> 23 | H23: =IFERROR(__xludf.DUMMYFUNCTION("""COMPUTED_VALUE"""),3.0) -> 3
A24: 23 | B24: =IFERROR(__xludf.DUMMYFUNCTION("""COMPUTED_VALUE"""),14.0) -> 14 | C24: =IFERROR(__xludf.DUMMYFUNCTION("""COMPUTED_VALUE"""),"Marcos Llorente") -> Marcos Llorente | D24: =IFERROR(__xludf.DUMMYFUNCTION("""COMPUTED_VALUE"""),"obrońca") -> obrońca | E24: =IFERROR(__xludf.DUMMYFUNCTION("""COMPUTED_VALUE"""),"Hiszpania") -> Hiszpania | F24: =IFERROR(__xludf.DUMMYFUNCTION("""COMPUTED_VALUE"""),34729.0) -> 34729 | G24: =IFERROR(__xludf.DUMMYFUNCTION("""COMPUTED_VALUE"""),30.0) -> 30 | H24: =IFERROR(__xludf.DUMMYFUNCTION("""COMPUTED_VALUE"""),3.0) -> 3
A25: 24 | B25: =IFERROR(__xludf.DUMMYFUNCTION("""COMPUTED_VALUE"""),8.0) -> 8 | C25: =IFERROR(__xludf.DUMMYFUNCTION("""COMPUTED_VALUE"""),"Felix Nmecha") -> Felix Nmecha | D25: =IFERROR(__xludf.DUMMYFUNCTION("""COMPUTED_VALUE"""),"pomocnik") -> pomocnik | E25: =IFERROR(__xludf.DUMMYFUNCTION("""COMPUTED_VALUE"""),"Niemcy /Anglia") -> Niemcy /Anglia | F25: =IFERROR(__xludf.DUMMYFUNCTION("""COMPUTED_VALUE"""),36809.0) -> 36809 | G25: =IFERROR(__xludf.DUMMYFUNCTION("""COMPUTED_VALUE"""),25.0) -> 25 | H25: =IFERROR(__xludf.DUMMYFUNCTION("""COMPUTED_VALUE"""),3.0) -> 3
A26: 25 | B26: =IFERROR(__xludf.DUMMYFUNCTION("""COMPUTED_VALUE"""),9.0) -> 9 | C26: =IFERROR(__xludf.DUMMYFUNCTION("""COMPUTED_VALUE"""),"Serhou Guirassy") -> Serhou Guirassy | D26: =IFERROR(__xludf.DUMMYFUNCTION("""COMPUTED_VALUE"""),"napastnik") -> napastnik | E26: =IFERROR(__xludf.DUMMYFUNCTION("""COMPUTED_VALUE"""),"Gwinea /Mali") -> Gwinea /Mali | F26: =IFERROR(__xludf.DUMMYFUNCTION("""COMPUTED_VALUE"""),35136.0) -> 35136 | G26: =IFERROR(__xludf.DUMMYFUNCTION("""COMPUTED_VALUE"""),29.0) -> 29 | H26: =IFERROR(__xludf.DUMMYFUNCTION("""COMPUTED_VALUE"""),3.0) -> 3
A27: 26 | B27: =IFERROR(__xludf.DUMMYFUNCTION("""COMPUTED_VALUE"""),10.0) -> 10 | C27: =IFERROR(__xludf.DUMMYFUNCTION("""COMPUTED_VALUE"""),"Julian Brandt") -> Julian Brandt | D27: =IFERROR(__xludf.DUMMYFUNCTION("""COMPUTED_VALUE"""),"pomocnik") -> pomocnik | E27: =IFERROR(__xludf.DUMMYFUNCTION("""COMPUTED_VALUE"""),"Niemcy") -> Niemcy | F27: =IFERROR(__xludf.DUMMYFUNCTION("""COMPUTED_VALUE"""),35187.0) -> 35187 | G27: =IFERROR(__xludf.DUMMYFUNCTION("""COMPUTED_VALUE"""),29.0) -> 29 | H27: =IFERROR(__xludf.DUMMYFUNCTION("""COMPUTED_VALUE"""),3.0) -> 3
A28: 27 | B28: =IFERROR(__xludf.DUMMYFUNCTION("""COMPUTED_VALUE"""),14.0) -> 14 | C28: =IFERROR(__xludf.DUMMYFUNCTION("""COMPUTED_VALUE"""),"Luis Díaz") -> Luis Díaz | D28: =IFERROR(__xludf.DUMMYFUNCTION("""COMPUTED_VALUE"""),"napastnik") -> napastnik | E28: =IFERROR(__xludf.DUMMYFUNCTION("""COMPUTED_VALUE"""),"Kolumbia") -> Kolumbia | F28: =IFERROR(__xludf.DUMMYFUNCTION("""COMPUTED_VALUE"""),35443.0) -> 35443 | G28: =IFERROR(__xludf.DUMMYFUNCTION("""COMPUTED_VALUE"""),29.0) -> 29 | H28: =IFERROR(__xludf.DUMMYFUNCTION("""COMPUTED_VALUE"""),3.0) -> 3
A29: 28 | B29: =IFERROR(__xludf.DUMMYFUNCTION("""COMPUTED_VALUE"""),42.0) -> 42 | C29: =IFERROR(__xludf.DUMMYFUNCTION("""COMPUTED_VALUE"""),"Lennart Karl") -> Lennart Karl | D29: =IFERROR(__xludf.DUMMYFUNCTION("""COMPUTED_VALUE"""),"pomocnik") -> pomocnik | E29: =IFERROR(__xludf.DUMMYFUNCTION("""COMPUTED_VALUE"""),"Niemcy") -> Niemcy | F29: =IFERROR(__xludf.DUMMYFUNCTION("""COMPUTED_VALUE"""),39500.0) -> 39500 | G29: =IFERROR(__xludf.DUMMYFUNCTION("""COMPUTED_VALUE"""),17.0) -> 17 | H29: =IFERROR(__xludf.DUMMYFUNCTION("""COMPUTED_VALUE"""),3.0) -> 3
A30: 29 | B30: =IFERROR(__xludf.DUMMYFUNCTION("""COMPUTED_VALUE"""),41.0) -> 41 | C30: =IFERROR(__xludf.DUMMYFUNCTION("""COMPUTED_VALUE"""),"Estêvão") -> Estêvão | D30: =IFERROR(__xludf.DUMMYFUNCTION("""COMPUTED_VALUE"""),"napastnik") -> napastnik | E30: =IFERROR(__xludf.DUMMYFUNCTION("""COMPUTED_VALUE"""),"Brazylia") -> Brazylia | F30: =IFERROR(__xludf.DUMMYFUNCTION("""COMPUTED_VALUE"""),39196.0) -> 39196 | G30: =IFERROR(__xludf.DUMMYFUNCTION("""COMPUTED_VALUE"""),18.0) -> 18 | H30: =IFERROR(__xludf.DUMMYFUNCTION("""COMPUTED_VALUE"""),3.0) -> 3
A31: 30 | B31: =IFERROR(__xludf.DUMMYFUNCTION("""COMPUTED_VALUE"""),11.0) -> 11 | C31: =IFERROR(__xludf.DUMMYFUNCTION("""COMPUTED_VALUE"""),"Jordan Larsson") -> Jordan Larsson | D31: =IFERROR(__xludf.DUMMYFUNCTION("""COMPUTED_VALUE"""),"napastnik") -> napastnik | E31: =IFERROR(__xludf.DUMMYFUNCTION("""COMPUTED_VALUE"""),"Szwecja /Curaçao") -> Szwecja /Curaçao | F31: =IFERROR(__xludf.DUMMYFUNCTION("""COMPUTED_VALUE"""),35601.0) -> 35601 | G31: =IFERROR(__xludf.DUMMYFUNCTION("""COMPUTED_VALUE"""),28.0) -> 28 | H31: =IFERROR(__xludf.DUMMYFUNCTION("""COMPUTED_VALUE"""),3.0) -> 3
A32: 31 | B32: =IFERROR(__xludf.DUMMYFUNCTION("""COMPUTED_VALUE"""),9.0) -> 9 | C32: =IFERROR(__xludf.DUMMYFUNCTION("""COMPUTED_VALUE"""),"Jonathan Burkardt") -> Jonathan Burkardt | D32: =IFERROR(__xludf.DUMMYFUNCTION("""COMPUTED_VALUE"""),"napastnik") -> napastnik | E32: =IFERROR(__xludf.DUMMYFUNCTION("""COMPUTED_VALUE"""),"Niemcy") -> Niemcy | F32: =IFERROR(__xludf.DUMMYFUNCTION("""COMPUTED_VALUE"""),36718.0) -> 36718 | G32: =IFERROR(__xludf.DUMMYFUNCTION("""COMPUTED_VALUE"""),25.0) -> 25 | H32: =IFERROR(__xludf.DUMMYFUNCTION("""COMPUTED_VALUE"""),3.0) -> 3
A33: 32 | B33: =IFERROR(__xludf.DUMMYFUNCTION("""COMPUTED_VALUE"""),9.0) -> 9 | C33: =IFERROR(__xludf.DUMMYFUNCTION("""COMPUTED_VALUE"""),"Dušan Vlahović") -> Dušan Vlahović | D33: =IFERROR(__xludf.DUMMYFUNCTION("""COMPUTED_VALUE"""),"napastnik") -> napastnik | E33: =IFERROR(__xludf.DUMMYFUNCTION("""COMPUTED_VALUE"""),"Serbia") -> Serbia | F33: =IFERROR(__xludf.DUMMYFUNCTION("""COMPUTED_VALUE"""),36553.0) -> 36553 | G33: =IFERROR(__xludf.DUMMYFUNCTION("""COMPUTED_VALUE"""),26.0) -> 26 | H33: =IFERROR(__xludf.DUMMYFUNCTION("""COMPUTED_VALUE"""),3.0) -> 3
A34: 33 | B34: =IFERROR(__xludf.DUMMYFUNCTION("""COMPUTED_VALUE"""),22.0) -> 22 | C34: =IFERROR(__xludf.DUMMYFUNCTION("""COMPUTED_VALUE"""),"Weston McKennie") -> Weston McKennie | D34: =IFERROR(__xludf.DUMMYFUNCTION("""COMPUTED_VALUE"""),"pomocnik") -> pomocnik | E34: =IFERROR(__xludf.DUMMYFUNCTION("""COMPUTED_VALUE"""),"USA") -> USA | F34: =IFERROR(__xludf.DUMMYFUNCTION("""COMPUTED_VALUE"""),36035.0) -> 36035 | G34: =IFERROR(__xludf.DUMMYFUNCTION("""COMPUTED_VALUE"""),27.0) -> 27 | H34: =IFERROR(__xludf.DUMMYFUNCTION("""COMPUTED_VALUE"""),3.0) -> 3
A35: 34 | B35: =IFERROR(__xludf.DUMMYFUNCTION("""COMPUTED_VALUE"""),20.0) -> 20 | C35: =IFERROR(__xludf.DUMMYFUNCTION("""COMPUTED_VALUE"""),"Alejandro Grimaldo") -> Alejandro Grimaldo | D35: =IFERROR(__xludf.DUMMYFUNCTION("""COMPUTED_VALUE"""),"obrońca") -> obrońca | E35: =IFERROR(__xludf.DUMMYFUNCTION("""COMPUTED_VALUE"""),"Hiszpania") -> Hiszpania | F35: =IFERROR(__xludf.DUMMYFUNCTION("""COMPUTED_VALUE"""),34962.0) -> 34962 | G35: =IFERROR(__xludf.DUMMYFUNCTION("""COMPUTED_VALUE"""),30.0) -> 30 | H35: =IFERROR(__xludf.DUMMYFUNCTION("""COMPUTED_VALUE"""),3.0) -> 3
A36: 35 | B36: =IFERROR(__xludf.DUMMYFUNCTION("""COMPUTED_VALUE"""),10.0) -> 10 | C36: =IFERROR(__xludf.DUMMYFUNCTION("""COMPUTED_VALUE"""),"Mason Greenwood") -> Mason Greenwood | D36: =IFERROR(__xludf.DUMMYFUNCTION("""COMPUTED_VALUE"""),"napastnik") -> napastnik | E36: =IFERROR(__xludf.DUMMYFUNCTION("""COMPUTED_VALUE"""),"Anglia") -> Anglia | F36: =IFERROR(__xludf.DUMMYFUNCTION("""COMPUTED_VALUE"""),37165.0) -> 37165 | G36: =IFERROR(__xludf.DUMMYFUNCTION("""COMPUTED_VALUE"""),24.0) -> 24 | H36: =IFERROR(__xludf.DUMMYFUNCTION("""COMPUTED_VALUE"""),3.0) -> 3
A37: 36 | B37: =IFERROR(__xludf.DUMMYFUNCTION("""COMPUTED_VALUE"""),97.0) -> 97 | C37: =IFERROR(__xludf.DUMMYFUNCTION("""COMPUTED_VALUE"""),"Pierre-Emerick Aubameyang") -> Pierre-Emerick Aubameyang | D37: =IFERROR(__xludf.DUMMYFUNCTION("""COMPUTED_VALUE"""),"napastnik") -> napastnik | E37: =IFERROR(__xludf.DUMMYFUNCTION("""COMPUTED_VALUE"""),"Gabon /Francja") -> Gabon /Francja | F37: =IFERROR(__xludf.DUMMYFUNCTION("""COMPUTED_VALUE"""),32677.0) -> 32677 | G37: =IFERROR(__xludf.DUMMYFUNCTION("""COMPUTED_VALUE"""),36.0) -> 36 | H37: =IFERROR(__xludf.DUMMYFUNCTION("""COMPUTED_VALUE"""),3.0) -> 3
A38: 37 | B38: =IFERROR(__xludf.DUMMYFUNCTION("""COMPUTED_VALUE"""),9.0) -> 9 | C38: =IFERROR(__xludf.DUMMYFUNCTION("""COMPUTED_VALUE"""),"Folarin Balogun") -> Folarin Balogun | D38: =IFERROR(__xludf.DUMMYFUNCTION("""COMPUTED_VALUE"""),"napastnik") -> napastnik | E38: =IFERROR(__xludf.DUMMYFUNCTION("""COMPUTED_VALUE"""),"USA /Anglia") -> USA /Anglia | F38: =IFERROR(__xludf.DUMMYFUNCTION("""COMPUTED_VALUE"""),37075.0) -> 37075 | G38: =IFERROR(__xludf.DUMMYFUNCTION("""COMPUTED_VALUE"""),24.0) -> 24 | H38: =IFERROR(__xludf.DUMMYFUNCTION("""COMPUTED_VALUE"""),3.0) -> 3
A39: 38 | B39: =IFERROR(__xludf.DUMMYFUNCTION("""COMPUTED_VALUE"""),7.0) -> 7 | C39: =IFERROR(__xludf.DUMMYFUNCTION("""COMPUTED_VALUE"""),"Chwicza Kwaracchelia") -> Chwicza Kwaracchelia | D39: =IFERROR(__xludf.DUMMYFUNCTION("""COMPUTED_VALUE"""),"napastnik") -> napastnik | E39: =IFERROR(__xludf.DUMMYFUNCTION("""COMPUTED_VALUE"""),"Gruzja") -> Gruzja | F39: =IFERROR(__xludf.DUMMYFUNCTION("""COMPUTED_VALUE"""),36934.0) -> 36934 | G39: =IFERROR(__xludf.DUMMYFUNCTION("""COMPUTED_VALUE"""),24.0) -> 24 | H39: =IFERROR(__xludf.DUMMYFUNCTION("""COMPUTED_VALUE"""),3.0) -> 3
A40: 39 | B40: =IFERROR(__xludf.DUMMYFUNCTION("""COMPUTED_VALUE"""),9.0) -> 9 | C40: =IFERROR(__xludf.DUMMYFUNCTION("""COMPUTED_VALUE"""),"Ricardo Pepi") -> Ricardo Pepi | D40: =IFERROR(__xludf.DUMMYFUNCTION("""COMPUTED_VALUE"""),"napastnik") -> napastnik | E40: =IFERROR(__xludf.DUMMYFUNCTION("""COMPUTED_VALUE"""),"USA /Meksyk") -> USA /Meksyk | F40: =IFERROR(__xludf.DUMMYFUNCTION("""COMPUTED_VALUE"""),37630.0) -> 37630 | G40: =IFERROR(__xludf.DUMMYFUNCTION("""COMPUTED_VALUE"""),23.0) -> 23 | H40: =IFERROR(__xludf.DUMMYFUNCTION("""COMPUTED_VALUE"""),3.0) -> 3
...

Sheet Ajax
A1: t | B1: imię i nazwisko | C1: pozycja | D1: narodowość | E1: flaga | F1: data urodzenia | G1: wiek | H1: mecze | I1: minuty | J1: gole | K1: asysty | L1: żółte kartki | M1: czerwone kartki | N1: czyste konta | O1: kanadyjka | P1: obronione karne
A2: 1 | B2: Vítězslav Jaroš | C2: bramkarz | D2: Czechy | E2: =IMAGE("https://flagcdn.com/w320/cz.png") | F2: 37095 | G2: =DATEDIF(F2,TODAY(),"Y") -> 24 | H2: =1+1+1+1+1 -> 5 | I2: =90+90+90+90+90 -> 450 | O2: =J2+K2 -> 0
A3: 2 | B3: Lucas Rosa | C3: obrońca | D3: Brazylia /Włochy | E3: =IMAGE("https://flagcdn.com/w320/br.png") | F3: 36619 | G3: =DATEDIF(F3,TODAY(),"Y") -> 25 | H3: =1+1+1 -> 3 | I3: =90+83+90 -> 263 | K3: =1 -> 1 | L3: =1 -> 1 | O3: =J3+K3 -> 1
A4: 3 | B4: Anton Gaaei | C4: obrońca | D4: Dania | E4: =IMAGE("https://flagcdn.com/w320/dk.png") | F4: 37579 | G4: =DATEDIF(F4,TODAY(),"Y") -> 23 | H4: =1+1+1+1+1+1 -> 6 | I4: =90+36+7+90+90+90 -> 403 | J4: =1 -> 1 | K4: =1 -> 1 | L4: =1+1 -> 2 | O4: =J4+K4 -> 2
A5: 4 | B5: Kō Itakura | C5: obrońca | D5: Japonia | E5: =IMAGE("https://flagcdn.com/w320/jp.png") | F5: 35457 | G5: =DATEDIF(F5,TODAY(),"Y") -> 29 | H5: =1+1+1+1+1+1 -> 6 | I5: =83+90+90+90+64+37 -> 454 | L5: =1 -> 1 | O5: =J5+K5 -> 0
A6: 5 | B6: Owen Wijndal | C6: obrońca | D6: Holandia /Surinam | E6: =IMAGE("https://flagcdn.com/w320/nl.png") | F6: 36492 | G6: =DATEDIF(F6,TODAY(),"Y") -> 26 | H6: =1+1+1+1+1 -> 5 | I6: =90+54+45+59+83 -> 331 | L6: =1 -> 1 | O6: =J6+K6 -> 0
A7: 6 | B7: Youri Regger | C7: pomocnik | D7: Holandia | E7: =IMAGE("https://flagcdn.com/w320/nl.png") | F7: 37851 | G7: =DATEDIF(F7,TODAY(),"Y") -> 22 | H7: =1+1+1+1+1+1+1 -> 7 | I7: =75+22+12+69+82+26+53 -> 339 | O7: =J7+K7 -> 0
A8: 7 | B8: Raúl Moro | C8: napastnik | D8: Hiszpania | E8: =IMAGE("https://flagcdn.com/w320/es.png") | F8: 37595 | G8: =DATEDIF(F8,TODAY(),"Y") -> 23 | H8: =1+1+1+1+1 -> 5 | I8: =15+7+90+8+75 -> 195 | O8: =J8+K8 -> 0
A9: 8 | B9: Kenneth Taylor | C9: pomocnik | D9: Holandia | E9: =IMAGE("https://flagcdn.com/w320/nl.png") | F9: 37392 | G9: =DATEDIF(F9,TODAY(),"Y") -> 23 | H9: =1+1+1+1 -> 4 | I9: =62+90+14+90 -> 256 | M9: =1 -> 1 | O9: =J9+K9 -> 0
A10: 9 | B10: Kasper Dolberg | C10: napastnik | D10: Dania | E10: =IMAGE("https://flagcdn.com/w320/dk.png") | F10: 35709 | G10: =DATEDIF(F10,TODAY(),"Y") -> 28 | H10: =1+1+1+1 -> 4 | I10: =28+17+64+70 -> 179 | J10: =1 -> 1 | O10: =J10+K10 -> 1
A11: 10 | B11: Oscar Gloukh | C11: pomocnik | D11: Izrael | E11: =IMAGE("https://flagcdn.com/w320/il.png") | F11: 38078 | G11: =DATEDIF(F11,TODAY(),"Y") -> 21 | H11: =1+1+1+1+1+1+1 -> 7 | I11: =15+90+22+90+17+90+83 -> 407 | J11: =2+1 -> 3 | O11: =J11+K11 -> 3
A12: 11 | B12: Mika Godts | C12: napastnik | D12: Belgia | E12: =IMAGE("https://flagcdn.com/w320/be.png") | F12: 38510 | G12: =DATEDIF(F12,TODAY(),"Y") -> 20 | H12: =1+1+1+1+1+1+1 -> 7 | I12: =75+83+83+69+73+15+90 -> 488 | K12: =1 -> 1 | O12: =J12+K12 -> 1
A13: 12 | B13: Joeri Heerkens | C13: bramkarz | D13: Holandia /Czechy | E13: =IMAGE("https://flagcdn.com/w320/nl.png") | F13: 38845 | G13: =DATEDIF(F13,TODAY(),"Y") -> 19 | H13: 0 | I13: 0 | O13: =J13+K13 -> 0
A14: 15 | B14: Youri Baas | C14: obrońca | D14: Holandia | E14: =IMAGE("https://flagcdn.com/w320/nl.png") | F14: 37697 | G14: =DATEDIF(F14,TODAY(),"Y") -> 22 | H14: =1+1+1+1+1+1+1 -> 7 | I14: =90+54+90+90+90+90+90 -> 594 | L14: =1+1 -> 2 | O14: =J14+K14 -> 0
A15: 16 | B15: James McConnell | C15: pomocnik | D15: Anglia | E15: =IMAGE("https://flagcdn.com/w320/gb-eng.png") | F15: 38243 | G15: =DATEDIF(F15,TODAY(),"Y") -> 21 | H15: =1+1+1 -> 3 | I15: =28+78+12 -> 118 | L15: =1 -> 1 | O15: =J15+K15 -> 0
A16: 17 | B16: Oliver Edvardsen | C16: napastnik | D16: Norwegia | E16: =IMAGE("https://flagcdn.com/w320/no.png") | F16: 36238 | G16: =DATEDIF(F16,TODAY(),"Y") -> 26 | H16: =1+1+1 -> 3 | I16: =90+45+7 -> 142 | J16: =1 -> 1 | O16: =J16+K16 -> 1
A17: 18 | B17: Davy Klaassen | C17: pomocnik | D17: Holandia | E17: =IMAGE("https://flagcdn.com/w320/nl.png") | F17: 34021 | G17: =DATEDIF(F17,TODAY(),"Y") -> 32 | H17: =1+1+1+1+1+1+1 -> 7 | I17: =90+90+45+90+73+15+90 -> 493 | L17: =1 -> 1 | O17: =J17+K17 -> 0
A18: 19 | B18: Don-Angelo Konadu | C18: napastnik | D18: Holandia /Ghana | E18: =IMAGE("https://flagcdn.com/w320/nl.png") | F18: 38840 | G18: =DATEDIF(F18,TODAY(),"Y") -> 19 | H18: =1 -> 1 | I18: =26 -> 26 | K18: =1 -> 1 | O18: =J18+K18 -> 1
A19: 21 | B19: Branco van den Boomen | C19: pomocnik | D19: Holandia | E19: =IMAGE("https://flagcdn.com/w320/nl.png") | F19: 34901 | G19: =DATEDIF(F19,TODAY(),"Y") -> 30 | H19: 0 | I19: 0 | O19: =J19+K19 -> 0
A20: 22 | B20: Remko Pasveer | C20: bramkarz | D20: Holandia | E20: =IMAGE("https://flagcdn.com/w320/nl.png") | F20: 30628 | G20: =DATEDIF(F20,TODAY(),"Y") -> 42 | H20: =1+1 -> 2 | I20: =90+90 -> 180 | O20: =J20+K20 -> 0
A21: 23 | B21: Steven Berghuis | C21: napastnik | D21: Holandia | E21: =IMAGE("https://flagcdn.com/w320/nl.png") | F21: 33591 | G21: =DATEDIF(F21,TODAY(),"Y") -> 34 | H21: =1 -> 1 | I21: =45 -> 45 | O21: =J21+K21 -> 0
A22: 24 | B22: Jorthy Mokio | C22: pomocnik | D22: Belgia /Demokratyczna Republika Konga | E22: =IMAGE("https://flagcdn.com/w320/be.png") | F22: 39507 | G22: =DATEDIF(F22,TODAY(),"Y") -> 17 | H22: =1+1+1+1+1+1 -> 6 | I22: =68+68+78+31+83+70 -> 398 | L22: =1 -> 1 | O22: =J22+K22 -> 0
A23: 25 | B23: Wout Weghorst | C23: napastnik | D23: Holandia | E23: =IMAGE("https://flagcdn.com/w320/nl.png") | F23: 33823 | G23: =DATEDIF(F23,TODAY(),"Y") -> 33 | H23: =1+1+1+1 -> 4 | I23: =62+45+90+90 -> 287 | J23: =1 -> 1 | L23: =1+1 -> 2 | O23: =J23+K23 -> 1
A24: 28 | B24: Kian Fitz-Jim | C24: pomocnik | D24: Holandia /Surinam | E24: =IMAGE("https://flagcdn.com/w320/nl.png") | F24: 37807 | G24: =DATEDIF(F24,TODAY(),"Y") -> 22 | H24: =1+1+1+1+1 -> 5 | I24: =7+21+17+7+7 -> 59 | O24: =J24+K24 -> 0
A25: 30 | B25: Aaron Bouwman | C25: obrońca | D25: Holandia /Anglia | E25: =IMAGE("https://flagcdn.com/w320/nl.png") | F25: 39322 | G25: =DATEDIF(F25,TODAY(),"Y") -> 18 | H25: =1+1 -> 2 | I25: =90+90 -> 180 | L25: =1 -> 1 | O25: =J25+K25 -> 0
A26: 37 | B26: Josip Šutalo | C26: obrońca | D26: Chorwacja | E26: =IMAGE("https://flagcdn.com/w320/hr.png") | F26: 36584 | G26: =DATEDIF(F26,TODAY(),"Y") -> 25 | H26: =1+1+1+1+1 -> 5 | I26: =7+36+90+90+90 -> 313 | O26: =J26+K26 -> 0
A27: 41 | B27: Gerald Alders | C27: obrońca | D27: Holandia /Nambia | E27: =IMAGE("https://flagcdn.com/w320/nl.png") | F27: 38479 | G27: =DATEDIF(F27,TODAY(),"Y") -> 20 | H27: =1 -> 1 | I27: =45 -> 45 | O27: =J27+K27 -> 0
A28: 43 | B28: Rayane Bounida | C28: pomocnik | D28: Belgia /Maroko | E28: =IMAGE("https://flagcdn.com/w320/be.png") | F28: 38779 | G28: =DATEDIF(F28,TODAY(),"Y") -> 19 | H28: =1+1+1 -> 3 | I28: =21+73+20 -> 114 | O28: =J28+K28 -> 0
A29: 44 | B29: Mark Verkuijl | C29: pomocnik | D29: Holandia | E29: =IMAGE("https://flagcdn.com/w320/nl.png") | F29: 38758 | G29: =DATEDIF(F29,TODAY(),"Y") -> 19 | O29: =J29+K29 -> 0
A30: 45 | B30: Ryan van de Pavert | C30: obrońca | D30: Holandia | E30: =IMAGE("https://flagcdn.com/w320/nl.png") | F30: 38741 | G30: =DATEDIF(F30,TODAY(),"Y") -> 20 | O30: =J30+K30 -> 0
A31: 46 | B31: Lucas Jetten | C31: obrońca | D31: Holandia /RPA | E31: =IMAGE("https://flagcdn.com/w320/nl.png") | F31: 39240 | G31: =DATEDIF(F31,TODAY(),"Y") -> 18 | O31: =J31+K31 -> 0
A32: 48 | B32: Sean Steur | C32: pomocnik | D32: Holandia | E32: =IMAGE("https://flagcdn.com/w320/nl.png") | F32: 39458 | G32: =DATEDIF(F32,TODAY(),"Y") -> 18 | H32: =1+1 -> 2 | I32: =75+20 -> 95 | K32: =1 -> 1 | O32: =J32+K32 -> 1
A33: 49 | B33: Kayden Wolff | C33: napastnik | D33: Holandia /Surinam | E33: =IMAGE("https://flagcdn.com/w320/nl.png") | F33: 38887 | G33: =DATEDIF(F33,TODAY(),"Y") -> 19 | O33: =J33+K33 -> 0
A34: 51 | B34: Charlie Setford | C34: bramkarz | D34: Holandia /Anglia | E34: =IMAGE("https://flagcdn.com/w320/nl.png") | F34: 38118 | G34: =DATEDIF(F34,TODAY(),"Y") -> 21 | O34: =J34+K34 -> 0
A35: 52 | B35: Paul Reverson | C35: bramkarz | D35: Ghana /Holandia | E35: =IMAGE("https://flagcdn.com/w320/gh.png") | F35: 38523 | G35: =DATEDIF(F35,TODAY(),"Y") -> 20 | H35: 0 | I35: 0 | O35: =J35+K35 -> 0
A36: 53 | B36: Mylo van der Lans | C36: pomocnik | D36: Holandia | E36: =IMAGE("https://flagcdn.com/w320/nl.png") | F36: 39183 | G36: =DATEDIF(F36,TODAY(),"Y") -> 18 | H36: 0 | I36: 0
A37: 54 | B37: Skye Vink | C37: napastnik | D37: Holandia /Surinam | E37: =IMAGE("https://flagcdn.com/w320/nl.png") | F37: 38899 | G37: =DATEDIF(F37,TODAY(),"Y") -> 19
A38: 55 | B38: Tijn Peters | C38: pomocnik | D38: Holandia | E38: =IMAGE("https://flagcdn.com/w320/nl.png") | F38: 38779 | G38: =DATEDIF(F38,TODAY(),"Y") -> 19
A39: 56 | B39: David Kalokoh | C39: napastnik | D39: Holandia /Sierra Leone | E39: =IMAGE("https://flagcdn.com/w320/nl.png") | F39: 38463 | G39: =DATEDIF(F39,TODAY(),"Y") -> 20
A40: 57 | B40: Jinairo Johnson | C40: obrońca | D40: Holandia /Jamajka | E40: =IMAGE("https://flagcdn.com/w320/nl.png") | F40: 39180 | G40: =DATEDIF(F40,TODAY(),"Y") -> 18
...

Sheet Arsenal
A1: numer | B1: imię i nazwisko | C1: pozycja | D1: narodowość | E1: flaga | F1: data urodzenia | G1: wiek | H1: mecze | I1: minuty | J1: gole | K1: asysty | L1: żółte kartki | M1: czerwone kartki | N1: czyste konta | O1: kanadyjka | P1: obronione karne
A2: 1 | B2: David Raya | C2: bramkarz | D2: Hiszpania | E2: =IMAGE("https://flagcdn.com/w320/es.png") | F2: 34957 | G2: =DATEDIF(F2,TODAY(),"Y") -> 30 | H2: =1+1+1+1+1+1+1 -> 7 | I2: =90+90+90+90+90+90+90 -> 630 | N2: =1+1+1+1+1 -> 5 | O2: =J2+K2 -> 0
A3: 2 | B3: William Saliba | C3: obrońca | D3: Francja /Kamerun | E3: =IMAGE("https://flagcdn.com/w320/fr.png") | F3: 36974 | G3: =DATEDIF(F3,TODAY(),"Y") -> 24 | H3: =1+1+1+1+1 -> 5 | I3: =90+90+90+90+90 -> 450 | L3: =1 -> 1 | O3: =J3+K3 -> 0
A4: 3 | B4: Cristhian Mosquera | C4: obrońca | D4: Hiszpania /Kolumbia | E4: =IMAGE("https://flagcdn.com/w320/es.png") | F4: 38165 | G4: =DATEDIF(F4,TODAY(),"Y") -> 21 | H4: =1+1+1+1+1 -> 5 | I4: =90+16+19+90+74 -> 289 | O4: =J4+K4 -> 0
A5: 4 | B5: Ben White | C5: obrońca | D5: Anglia | E5: =IMAGE("https://flagcdn.com/w320/gb-eng.png") | F5: 35711 | G5: =DATEDIF(F5,TODAY(),"Y") -> 28 | H5: =1+1+1+1+1+1 -> 6 | I5: =57+8+18+11+82+27 -> 203 | L5: =1 -> 1 | O5: =J5+K5 -> 0
A6: 5 | B6: Piero Hincapié | C6: obrońca | D6: Ekwador | E6: =IMAGE("https://flagcdn.com/w320/ec.png") | F6: 37265 | G6: =DATEDIF(F6,TODAY(),"Y") -> 24 | H6: =1+1+1 -> 3 | I6: =1+72+62 -> 135 | O6: =J6+K6 -> 0
A7: 6 | B7: Gabriel Magalhães | C7: obrońca | D7: Brazylia | E7: =IMAGE("https://flagcdn.com/w320/br.png") | F7: 35783 | G7: =DATEDIF(F7,TODAY(),"Y") -> 28 | H7: =1+1+1+1+1 -> 5 | I7: =90+74+71+90+16 -> 341 | J7: =1 -> 1 | K7: =1 -> 1 | L7: =1 -> 1 | O7: =J7+K7 -> 2
A8: 7 | B8: Bukayo Saka | C8: napastnik | D8: Anglia /Nigeria | E8: =IMAGE("https://flagcdn.com/w320/gb-eng.png") | F8: 37139 | G8: =DATEDIF(F8,TODAY(),"Y") -> 24 | H8: =1+1+1+1+1+1 -> 6 | I8: =18+90+90+67+20+90 -> 375 | J8: =1+1 -> 2 | K8: =1+1 -> 2 | O8: =J8+K8 -> 4
A9: 8 | B9: Martin Ødegaard | C9: pomocnik | D9: Norwegia | E9: =IMAGE("https://flagcdn.com/w320/no.png") | F9: 36146 | G9: =DATEDIF(F9,TODAY(),"Y") -> 27 | H9: =1+1+1 -> 3 | I9: =90+11+71 -> 172 | K9: =1 -> 1 | O9: =J9+K9 -> 1
A10: 9 | B10: Gabriel Jesus | C10: napastnik | D10: Brazylia | E10: =IMAGE("https://flagcdn.com/w320/br.png") | F10: 35523 | G10: =DATEDIF(F10,TODAY(),"Y") -> 28 | H10: =1+1 -> 2 | I10: =29+74 -> 103 | J10: =2 -> 2 | O10: =J10+K10 -> 2
A11: 10 | B11: Eberechi Eze | C11: pomocnik | D11: Anglia /Nigeria | E11: =IMAGE("https://flagcdn.com/w320/gb-eng.png") | F11: 35975 | G11: =DATEDIF(F11,TODAY(),"Y") -> 27 | H11: =1+1+1+1+1+1 -> 6 | I11: =70+18+71+26+79+63 -> 327 | K11: =1+1 -> 2 | O11: =J11+K11 -> 2
A12: 11 | B12: Gabriel Martinelli | C12: napastnik | D12: Brazylia /Włochy | E12: =IMAGE("https://flagcdn.com/w320/br.png") | F12: 37060 | G12: =DATEDIF(F12,TODAY(),"Y") -> 24 | H12: =1+1+1+1+1+1 -> 6 | I12: =20+72+90+23+90+12 -> 307 | J12: =1+1+1+1+1 -> 5 | K12: =1 -> 1 | O12: =J12+K12 -> 6
A13: 12 | B13: Jurriën Timber | C13: obrońca | D13: Holandia /Curaçao | E13: =IMAGE("https://flagcdn.com/w320/nl.png") | F13: 37059 | G13: =DATEDIF(F13,TODAY(),"Y") -> 24 | H13: =1+1+1+1+1+1 -> 6 | I13: =90+33+82+72+79+63 -> 419 | J13: =1 -> 1 | O13: =J13+K13 -> 1
A14: 13 | B14: Kepa Arrizabalaga | C14: bramkarz | D14: Hiszpania | E14: =IMAGE("https://flagcdn.com/w320/es.png") | F14: 34610 | G14: =DATEDIF(F14,TODAY(),"Y") -> 31 | H14: =0 -> 0 | I14: =0 -> 0 | O14: =J14+K14 -> 0
A15: 14 | B15: Viktor Gyökeres | C15: napastnik | D15: Szwecja /Węgry | E15: =IMAGE("https://flagcdn.com/w320/se.png") | F15: 35950 | G15: =DATEDIF(F15,TODAY(),"Y") -> 27 | H15: =1+1+1+1+1 -> 5 | I15: =64+90+82+61+16 -> 313 | J15: =2+1 -> 3 | K15: =1 -> 1 | O15: =J15+K15 -> 4
A16: 16 | B16: Christian Nørgaard | C16: pomocnik | D16: Dania | E16: =IMAGE("https://flagcdn.com/w320/dk.png") | F16: 34403 | G16: =DATEDIF(F16,TODAY(),"Y") -> 31 | H16: =1+1+1+1 -> 4 | I16: =1+19+90+90 -> 200 | L16: =1+1 -> 2 | O16: =J16+K16 -> 0
A17: 19 | B17: Leandro Trossard | C17: napastnik | D17: Belgia | E17: =IMAGE("https://flagcdn.com/w320/be.png") | F17: 34672 | G17: =DATEDIF(F17,TODAY(),"Y") -> 31 | H17: =1+1+1+1+1 -> 5 | I17: =26+72+72+37+78 -> 285 | J17: =1 -> 1 | K17: =1+1+2 -> 4 | O17: =J17+K17 -> 5
A18: 20 | B18: Noni Madueke | C18: napastnik | D18: Anglia /Nigeria | E18: =IMAGE("https://flagcdn.com/w320/gb-eng.png") | F18: 37325 | G18: =DATEDIF(F18,TODAY(),"Y") -> 23 | H18: =1+1+1 -> 3 | I18: =89+53+70 -> 212 | J18: =1+2 -> 3 | L18: =1 -> 1 | O18: =J18+K18 -> 3
A19: 22 | B19: Ethan Nwaneri | C19: pomocnik | D19: Anglia /Nigeria | E19: =IMAGE("https://flagcdn.com/w320/gb-eng.png") | F19: 39162 | G19: =DATEDIF(F19,TODAY(),"Y") -> 18 | H19: =1+1+1 -> 3 | I19: =19+64+19 -> 102 | L19: =1 -> 1 | O19: =J19+K19 -> 0
A20: 23 | B20: Mikel Merino | C20: pomocnik | D20: Hiszpania | E20: =IMAGE("https://flagcdn.com/w320/es.png") | F20: 35238 | G20: =DATEDIF(F20,TODAY(),"Y") -> 29 | H20: =1+1+1+1+1+1+1 -> 7 | I20: =90+58+8+90+90+90+90 -> 516 | J20: =2 -> 2 | L20: =1+1+1 -> 3 | O20: =J20+K20 -> 2
A21: 29 | B21: Kai Havertz | C21: napastnik | D21: Niemcy | E21: =IMAGE("https://flagcdn.com/w320/de.png") | F21: 36322 | G21: =DATEDIF(F21,TODAY(),"Y") -> 26 | O21: =J21+K21 -> 0
A22: 33 | B22: Ricciardo Calafiori | C22: obrońca | D22: Włochy | E22: =IMAGE("https://flagcdn.com/w320/it.png") | F22: 37395 | G22: =DATEDIF(F22,TODAY(),"Y") -> 23 | H22: =1+1+1 -> 3 | I22: =89+23+28 -> 140 | K22: =1 -> 1 | O22: =J22+K22 -> 1
A23: 35 | B23: Tommy Setford | C23: bramkarz | D23: Anglia /Holandia | E23: =IMAGE("https://flagcdn.com/w320/gb-eng.png") | F23: 38789 | G23: =DATEDIF(F23,TODAY(),"Y") -> 19 | H23: =0 -> 0 | I23: =0 -> 0 | O23: =J23+K23 -> 0
A24: 36 | B24: Martín Zubimendi | C24: pomocnik | D24: Hiszpania | E24: =IMAGE("https://flagcdn.com/w320/es.png") | F24: 36496 | G24: =DATEDIF(F24,TODAY(),"Y") -> 26 | H24: =1+1+1+1+1+1 -> 6 | I24: =90+90+71+90+90+90 -> 521 | K24: =2 -> 2 | L24: =1+1+1 -> 3 | O24: =J24+K24 -> 2
A25: 38 | B25: Louie Copley | C25: pomocnik | D25: Anglia | E25: =IMAGE("https://flagcdn.com/w320/gb-eng.png") | F25: 39010 | G25: =DATEDIF(F25,TODAY(),"Y") -> 19 | H25: 0 | I25: 0 | O25: =J25+K25 -> 0
A26: 39 | B26: Harrison Dudziak | C26: pomocnik | D26: Anglia /Polska | E26: =IMAGE("https://flagcdn.com/w320/gb-eng.png") | F26: 38726 | G26: =DATEDIF(F26,TODAY(),"Y") -> 20 | O26: =J26+K26 -> 0
A27: 40 | B27: Sebastian Ferdinand | C27: napastnik | D27: Anglia | E27: =IMAGE("https://flagcdn.com/w320/gb-eng.png") | F27: 38729 | G27: =DATEDIF(F27,TODAY(),"Y") -> 20 | O27: =J27+K27 -> 0
A28: 41 | B28: Declan Rice | C28: pomocnik | D28: Anglia /Irlandia | E28: =IMAGE("https://flagcdn.com/w320/gb-eng.png") | F28: 36174 | G28: =DATEDIF(F28,TODAY(),"Y") -> 27 | H28: =1+1+1+1+1+1 -> 6 | I28: =90+32+90+80+90+27 -> 409 | K28: =1+1 -> 2 | L28: =1+1+1 -> 3 | O28: =J28+K28 -> 2
A29: 42 | B29: Cam'ron Ismail | C29: obrońca | D29: Egipt /Anglia | E29: =IMAGE("https://flagcdn.com/w320/eg.png") | F29: 39043 | G29: =DATEDIF(F29,TODAY(),"Y") -> 19 | O29: =J29+K29 -> 0
A30: 44 | B30: Maldini Kacurri | C30: obrońca | D30: Albania /Anglia | E30: =IMAGE("https://flagcdn.com/w320/al.png") | F30: 38629 | G30: =DATEDIF(F30,TODAY(),"Y") -> 20 | O30: =J30+K30 -> 0
A31: 45 | B31: Osman Kamara | C31: napastnik | D31: Sierra Leone /Anglia | E31: =IMAGE("https://flagcdn.com/w320/sl.png") | F31: 38935 | G31: =DATEDIF(F31,TODAY(),"Y") -> 19 | O31: =J31+K31 -> 0
A32: 48 | B32: Josh Nichols | C32: obrońca | D32: Anglia /Nigeria | E32: =IMAGE("https://flagcdn.com/w320/gb-eng.png") | F32: 38924 | G32: =DATEDIF(F32,TODAY(),"Y") -> 19 | H32: 0 | I32: 0 | O32: =J32+K32 -> 0
A33: 49 | B33: Myles Lewis-Skelly | C33: obrońca | D33: Anglia /Barbados | E33: =IMAGE("https://flagcdn.com/w320/gb-eng.png") | F33: 38986 | G33: =DATEDIF(F33,TODAY(),"Y") -> 19 | H33: =1+1+1+1+1+1 -> 6 | I33: =90+90+18+67+90+90 -> 445 | K33: =1+1 -> 2 | L33: =1 -> 1 | O33: =J33+K33 -> 2
A34: 50 | B34: Daniel Oyetunde | C34: napastnik | D34: Anglia /Nigeria | E34: =IMAGE("https://flagcdn.com/w320/gb-eng.png") | F34: 39047 | G34: =DATEDIF(F34,TODAY(),"Y") -> 19 | O34: =J34+K34 -> 0
A35: 51 | B35: Alexéi Rojas | C35: bramkarz | D35: Kolumbia /Anglia | E35: =IMAGE("https://flagcdn.com/w320/co.png") | F35: 38623 | G35: =DATEDIF(F35,TODAY(),"Y") -> 20 | O35: =J35+K35 -> 0
A36: 53 | B36: Charles Sagoe Jr | C36: pomocnik | D36: Anglia /Ghana | E36: =IMAGE("https://flagcdn.com/w320/gb-eng.png") | F36: 38192 | G36: =DATEDIF(F36,TODAY(),"Y") -> 21 | H36: 0 | I36: 0 | O36: =J36+K36 -> 0
A37: 54 | B37: William Sweet | C37: obrońca | D37: Walia /Anglia | E37: =IMAGE("https://flagcdn.com/w320/gb-wls.png") | F37: 38992 | G37: =DATEDIF(F37,TODAY(),"Y") -> 19 | O37: =J37+K37 -> 0
A38: 56 | B38: Max Dowman | C38: pomocnik | D38: Anglia | E38: =IMAGE("https://flagcdn.com/w320/gb-eng.png") | F38: 40168 | G38: =DATEDIF(F38,TODAY(),"Y") -> 16 | H38: =1 -> 1 | I38: =18 -> 18 | O38: =J38+K38 -> 0
A39: 70 | B39: Samuel Chapman | C39: obrońca | D39: Anglia | E39: =IMAGE("https://flagcdn.com/w320/gb-eng.png") | F39: 39365 | G39: =DATEDIF(F39,TODAY(),"Y") -> 18 | O39: =J39+K39 -> 0
A40: 71 | B40: Andre Harriman-Annous | C40: pomocnik | D40: Anglia | E40: =IMAGE("https://flagcdn.com/w320/gb-eng.png") | F40: 39443 | G40: =DATEDIF(F40,TODAY(),"Y") -> 18 | H40: =1 -> 1 | I40: =10 -> 10 | O40: =J40+K40 -> 0
...

Sheet Atalanta
A1: numer | B1: imię i nazwisko | C1: pozycja | D1: narodowość | E1: flaga | F1: data urodzenia | G1: wiek | H1: mecze | I1: minuty | J1: gole | K1: asysty | L1: żółte kartki | M1: czerwone kartki | N1: czyste konta | O1: kandyjka | P1: obronione karne
A2: 3 | B2: Odilon Kossounou | C2: obrońca | D2: Wybrzeże Kości Słoniowej | E2: =IMAGE("https://flagcdn.com/w320/ci.png") | F2: 36895 | G2: =DATEDIF(F2,TODAY(),"Y") -> 25 | H2: =1+1+1+1+1+1+1 -> 7 | I2: =90+52+90+54+90+90+90 -> 556 | O2: =J2+K2 -> 0
A3: 4 | B3: Isak Hien | C3: obrońca | D3: Szwecja /Ghana | E3: =IMAGE("https://flagcdn.com/w320/se.png") | F3: 36173 | G3: =DATEDIF(F3,TODAY(),"Y") -> 27 | H3: =1+1+1+1 -> 4 | I3: =90+90+36+90 -> 306 | O3: =J3+K3 -> 0
A4: 5 | B4: Mitchel Bakker | C4: obrońca | D4: Holandia | E4: =IMAGE("https://flagcdn.com/w320/nl.png") | F4: 36697 | G4: =DATEDIF(F4,TODAY(),"Y") -> 25 | O4: =J4+K4 -> 0
A5: 6 | B5: Yunus Musah | C5: pomocnik | D5: USA /Anglia | E5: =IMAGE("https://flagcdn.com/w320/us.png") | F5: 37589 | G5: =DATEDIF(F5,TODAY(),"Y") -> 23 | H5: =1+1+1+1+1 -> 5 | I5: =74+38+16+22+4 -> 154 | K5: =1 -> 1 | L5: =1+1 -> 2 | O5: =J5+K5 -> 1
A6: 7 | B6: Kamaldeen Sulemana | C6: napastnik | D6: Ghana | E6: =IMAGE("https://flagcdn.com/w320/gh.png") | F6: 37302 | G6: =DATEDIF(F6,TODAY(),"Y") -> 23 | H6: =1+1+1+1 -> 4 | I6: =30+29+9+9 -> 77 | O6: =J6+K6 -> 0
A7: 8 | B7: Mario Pašalić | C7: pomocnik | D7: Chorwacja | E7: =IMAGE("https://flagcdn.com/w320/hr.png") | F7: 34739 | G7: =DATEDIF(F7,TODAY(),"Y") -> 30 | H7: =1+1+1+1 -> 4 | I7: =90+90+45+4 -> 229 | J7: =1 -> 1 | O7: =J7+K7 -> 1
A8: 9 | B8: Gianluca Scamacca | C8: napastnik | D8: Włochy | E8: =IMAGE("https://flagcdn.com/w320/it.png") | F8: 36161 | G8: =DATEDIF(F8,TODAY(),"Y") -> 27 | H8: =1+1+1+1+1 -> 5 | I8: =29+7+68+70+65 -> 239 | J8: =1+1 -> 2 | K8: =1 -> 1 | O8: =J8+K8 -> 3
A9: 10 | B9: Lazar Samardžić | C9: pomocnik | D9: Serbia /Niemcy | E9: =IMAGE("https://flagcdn.com/w320/rs.png") | F9: 37311 | G9: =DATEDIF(F9,TODAY(),"Y") -> 23 | H9: =1+1+1+1+1 -> 5 | I9: =45+30+1+7+15 -> 98 | J9: =1+1 -> 2 | O9: =J9+K9 -> 2
A10: 11 | B10: Ademola Lookman | C10: napastnik | D10: Nigeria /Anglia | E10: =IMAGE("https://flagcdn.com/w320/ng.png") | F10: 35723 | G10: =DATEDIF(F10,TODAY(),"Y") -> 28 | H10: =1+1+1+1+1+1 -> 6 | I10: =60+61+74+81+86+25 -> 387 | J10: =1 -> 1 | K10: =1+1 -> 2 | O10: =J10+K10 -> 3
A11: 13 | B11: Éderson | C11: pomocnik | D11: Brazylia | E11: =IMAGE("https://flagcdn.com/w320/br.png") | F11: 36348 | G11: =DATEDIF(F11,TODAY(),"Y") -> 26 | H11: =1+1+1+1+1+1 -> 6 | I11: =60+90+90+68+86+90 -> 484 | J11: =1 -> 1 | L11: =1 -> 1 | O11: =J11+K11 -> 1
A12: 15 | B12: Marten de Roon | C12: pomocnik | D12: Holandia | E12: =IMAGE("https://flagcdn.com/w320/nl.png") | F12: 33326 | G12: =DATEDIF(F12,TODAY(),"Y") -> 34 | H12: =1+1+1+1+1+1+1 -> 7 | I12: =90+90+90+45+90+90+90 -> 585 | K12: =1 -> 1 | L12: =1+1 -> 2 | O12: =J12+K12 -> 1
A13: 16 | B13: Raoul Bellanova | C13: pomocnik | D13: Włochy | E13: =IMAGE("https://flagcdn.com/w320/it.png") | F13: 36663 | G13: =DATEDIF(F13,TODAY(),"Y") -> 25 | H13: =1+1+1+1+1+1 -> 6 | I13: =90+45+17+90+90+16 -> 348 | L13: =1 -> 1 | O13: =J13+K13 -> 0
A14: 17 | B14: Charles De Keteleare | C14: pomocnik | D14: Belgia | E14: =IMAGE("https://flagcdn.com/w320/be.png") | F14: 36960 | G14: =DATEDIF(F14,TODAY(),"Y") -> 24 | H14: =1+1+1+1+1+1 -> 6 | I14: =45+89+83+90+90+90 -> 487 | J14: =1+1 -> 2 | K14: =1+1 -> 2 | O14: =J14+K14 -> 4
A15: 19 | B15: Berat Djimsiti | C15: obrońca | D15: Albania /Szwajcaria | E15: =IMAGE("https://flagcdn.com/w320/al.png") | F15: 34019 | G15: =DATEDIF(F15,TODAY(),"Y") -> 32 | H15: =1+1+1+1+1+1+1 -> 7 | I15: =74+90+90+90+73+90+90 -> 597 | L15: =1 -> 1 | O15: =J15+K15 -> 0
A16: 23 | B16: Sead Kolašinac | C16: obrońca | D16: Bośnia i Hercegowina /Niemcy | E16: =IMAGE("https://flagcdn.com/w320/ba.png") | F16: 34140 | G16: =DATEDIF(F16,TODAY(),"Y") -> 32 | H16: =1+1+1 -> 3 | I16: =17+70+75 -> 162 | O16: =J16+K16 -> 0
A17: 29 | B17: Marco Carnesecchi | C17: bramkarz | D17: Włochy | E17: =IMAGE("https://flagcdn.com/w320/it.png") | F17: 36708 | G17: =DATEDIF(F17,TODAY(),"Y") -> 25 | H17: =1+1+1+1+1+1+1 -> 7 | I17: =90+90+90+90+90+90+90 -> 630 | L17: =1 -> 1 | N17: =1+1+1 -> 3 | O17: =J17+K17 -> 0 | P17: =1 -> 1
A18: 31 | B18: Francesco Rossi | C18: bramkarz | D18: Włochy | E18: =IMAGE("https://flagcdn.com/w320/it.png") | F18: 33355 | G18: =DATEDIF(F18,TODAY(),"Y") -> 34 | H18: 0 | I18: 0 | O18: =J18+K18 -> 0
